<sdf version="1.7">
    <model name="ads-dv">

        <link name="chassis">
            <pose>0 0 0.5 0 0 0</pose>

            <collision name="collision">
                <pose>0 0 0 0 0 0</pose>

                <geometry>
                    <mesh>
                        <uri>model://ads-dv-hq/meshes/mesh.dae</uri>
                    </mesh>
                </geometry>
            </collision>

            <visual name="visual">
                <pose>0 0 0 0 0 0 0</pose>
                <geometry>
                    <mesh>
                        <uri>model://ads-dv-hq/meshes/mesh.dae</uri>
                    </mesh>
                </geometry>
            </visual>

            <inertial>
                <mass>125</mass> <!-- used for physics dynamics [kg] -->
                <inertia>
                    <ixx>25.417</ixx>
                    <iyy>92.9</iyy>
                    <izz>97.49</izz>
                    <ixy>0</ixy>
                    <ixz>0</ixz>
                    <iyz>0</iyz>
                </inertia>
            </inertial>
        </link>

        <link name="rear_right_wheel">
            <pose>-0.8 -0.6005 0.5 1.57079633 0.0 0.0</pose>

            <collision name="collision">
                <geometry>
                    <cylinder>
                        <radius>0.25025</radius>
                        <length>0.18288</length>
                    </cylinder>
                </geometry>

                <surface>
                    <friction>
                        <torsional>
                            <coefficient>1.0</coefficient>
                            <surface_radius>0.25025</surface_radius>
                            <use_patch_radius>true</use_patch_radius>
                        </torsional>

                        <ode>
                            <mu>1.2</mu>
                            <mu2>1.2</mu2>
                        </ode>
                    </friction>

                    <contact>
                        <ode>
                            <min_depth>0.005</min_depth>
                        </ode>
                    </contact>
                </surface>
            </collision>

            <visual name="visual">
                <geometry>
                    <mesh>
                        <uri>model://ads-dv-hq/meshes/wheel.dae</uri>
                    </mesh>
                </geometry>
            </visual>

            <inertial>
                <mass>5.7</mass>
                <inertia>
                    <ixx>0.223496</ixx>
                    <iyy>0.223496</iyy>
                    <izz>1</izz> <!-- car flips if changed -->
                    <iyz>0</iyz>
                    <ixy>0</ixy>
                    <ixz>0</ixz>
                </inertia>
            </inertial>
        </link>

        <joint type="revolute" name="rear_right_joint">
            <pose>0 0 0 0 0 0</pose>  <!-- Position of the Joint must be 0 0 0, as it is on the center of the wheel-->
            <parent>chassis</parent>
            <child>rear_right_wheel</child>
            <axis>
                <xyz>0 0 -1</xyz>
                <dynamics>
                    <friction>12.031606150200002</friction>
                </dynamics>
            </axis>
        </joint>

        <link name="rear_left_wheel">
            <pose>-0.8 0.6005 0.5 -1.57079633 0.0 0.0</pose>

            <collision name="collision">
                <geometry>
                    <cylinder>
                        <radius>0.25025</radius>
                        <length>0.18288</length>
                    </cylinder>
                </geometry>

                <surface>
                    <friction>
                        <torsional>
                            <coefficient>1.0</coefficient>
                            <surface_radius>0.25025</surface_radius>
                            <use_patch_radius>true</use_patch_radius>
                        </torsional>

                        <ode>
                            <mu>1.2</mu>
                            <mu2>1.2</mu2>
                        </ode>
                    </friction>


                    <contact>
                        <ode>
                            <min_depth>0.005</min_depth>
                        </ode>
                    </contact>
                </surface>
            </collision>

            <visual name="visual">
                <geometry>
                    <mesh>
                        <uri>model://ads-dv-hq/meshes/wheel.dae</uri>
                    </mesh>
                </geometry>
            </visual>

            <inertial>
                <mass>5.7</mass>
                <inertia>
                    <ixx>0.223496</ixx>
                    <iyy>0.223496</iyy>
                    <izz>0.39125</izz>
                    <iyz>0</iyz>
                    <ixy>0</ixy>
                    <ixz>0</ixz>
                </inertia>
            </inertial>
        </link>

        <joint type="revolute" name="rear_left_joint">
            <pose>0 0 0 0 0 0</pose>
            <child>rear_left_wheel</child>
            <parent>chassis</parent>
            <axis>
                <xyz>0 0 1</xyz>
                <dynamics>
                    <friction>12.031606150200002</friction>
                </dynamics>
            </axis>
        </joint>

        <link name="front_right_wheel">
            <pose>0.8 -0.6005 0.5 -1.57079633 0.0 0.0</pose>

            <collision name="collision">
                <geometry>
                    <cylinder>
                        <radius>0.25025</radius>
                        <length>0.18288</length>
                    </cylinder>
                </geometry>

                <surface>
                    <friction>
                        <torsional>
                            <coefficient>1.0</coefficient>
                            <surface_radius>0.25025</surface_radius>
                            <use_patch_radius>true</use_patch_radius>
                        </torsional>

                        <ode>
                            <mu>1.2</mu>
                            <mu2>1.2</mu2>
                        </ode>
                    </friction>

                    <contact>
                        <ode>
                            <min_depth>0.005</min_depth>
                        </ode>
                    </contact>
                </surface>
            </collision>

            <visual name="visual">
                <pose>0 0 0 3.14159266 0.0 0.0</pose>
                <geometry>
                    <mesh>
                        <uri>model://ads-dv-hq/meshes/wheel.dae</uri>
                    </mesh>
                </geometry>
            </visual>

            <inertial>
                <mass>5.7</mass>
                <inertia>
                    <ixx>0.223496</ixx>
                    <iyy>0.223496</iyy>
                    <izz>0.39125</izz>
                    <iyz>0</iyz>
                    <ixy>0</ixy>
                    <ixz>0</ixz>
                </inertia>
            </inertial>
        </link>

        <joint type="universal" name="front_right_combined_joint">
            <pose>0 0 0 0 0 0</pose>
            <child>front_right_wheel</child>
            <parent>chassis</parent>
            <axis>
                <xyz>0 -1 0</xyz>
                <limit>
                    <!-- +- 50 degrees -->
                    <lower>-0.8727</lower>
                    <upper>0.8727</upper>
                </limit>
            </axis>
            <axis2>
                <xyz>0 0 1</xyz>
                <dynamics>
                    <friction>18.0474092253</friction>
                </dynamics>
            </axis2>
        </joint>

        <link name="front_left_wheel">
            <pose>0.8 0.6005 0.5 -1.57079633 0.0 0.0</pose>

            <collision name="collision">
                <geometry>
                    <cylinder>
                        <radius>0.25025</radius>
                        <length>0.18288</length>
                    </cylinder>
                </geometry>

                <surface>
                    <friction>
                        <torsional>
                            <coefficient>1.0</coefficient>
                            <surface_radius>0.25025</surface_radius>
                            <use_patch_radius>true</use_patch_radius>
                        </torsional>

                        <ode>
                            <mu>1.2</mu>
                            <mu2>1.2</mu2>
                        </ode>
                    </friction>


                    <contact>
                        <ode>
                            <min_depth>0.005</min_depth>
                        </ode>
                    </contact>
                </surface>
            </collision>

            <visual name="visual">
                <geometry>
                    <mesh>
                        <uri>model://ads-dv-hq/meshes/wheel.dae</uri>
                    </mesh>
                </geometry>
            </visual>

            <inertial>
                <mass>5.7</mass>
                <inertia>
                    <ixx>0.223496</ixx>
                    <iyy>0.223496</iyy>
                    <izz>0.39125</izz>
                    <iyz>0</iyz>
                    <ixy>0</ixy>
                    <ixz>0</ixz>
                </inertia>
            </inertial>
        </link>

        <joint type="universal" name="front_left_combined_joint">
            <pose>0 0 0 0 0 0</pose>
            <child>front_left_wheel</child>
            <parent>chassis</parent>
            <axis>
                <xyz>0 -1 0</xyz>
                <limit>
                    <!-- +- 50 degrees -->
                    <lower>-0.8727</lower>
                    <upper>0.8727</upper>
                </limit>
            </axis>
            <axis2>
                <xyz>0 0 1</xyz>
                <dynamics>
                    <friction>18.0474092253</friction>
                </dynamics>
            </axis2>
        </joint>

        <plugin name="gazebo_ros_ackermann_drive" filename="libgazebo_ros_ackermann_drive.so">
            <ros>
                <namespace>/gazebo</namespace>
                <remapping>cmd_vel:=cmd_vel</remapping>
                <remapping>odom:=odom</remapping>
                <remapping>distance:=distance</remapping>
            </ros>
            <update_rate>100.0</update_rate>
            <!-- wheels -->
            <front_left_joint>front_left_combined_joint</front_left_joint>
            <front_right_joint>front_right_combined_joint</front_right_joint>
            <rear_left_joint>rear_left_joint</rear_left_joint>
            <rear_right_joint>rear_right_joint</rear_right_joint>
            <left_steering_joint>front_left_combined_joint</left_steering_joint>
            <right_steering_joint>front_right_combined_joint</right_steering_joint>

            <!-- Max absolute steer angle for tyre in radians--> <!-- Any cmd_vel angular z greater than this would be capped -->
            <max_steer>0.4747296</max_steer> <!-- 27.2 deg-->
            <!-- Max absolute steering angle of steering wheel -->
            <max_steering_angle>3.14</max_steering_angle> <!-- 180 deg-->
            <!-- Max absolute linear speed in m/s -->
            <max_speed>20</max_speed> <!-- Real one should be around 50 m/s-->
            <!-- PID tuning -->
            <left_steering_pid_gain>1000 0 1</left_steering_pid_gain>
            <left_steering_i_range>0 0</left_steering_i_range>
            <right_steering_pid_gain>1000 0 1</right_steering_pid_gain>
            <right_steering_i_range>0 0</right_steering_i_range>
            <linear_velocity_pid_gain>1000 0 1</linear_velocity_pid_gain>
            <linear_velocity_i_range>0 0</linear_velocity_i_range>
            <!-- output -->
            <publish_odom>true</publish_odom>
            <publish_odom_tf>true</publish_odom_tf>
            <publish_wheel_tf>true</publish_wheel_tf>
            <publish_distance>true</publish_distance>
            <odometry_frame>odom_demo</odometry_frame>
            <robot_base_frame>chassis</robot_base_frame>
        </plugin>
        <include>
            <uri>model://zed_camera</uri>
            <pose>0.9 0 0.765 0 0 0</pose>
        </include>

        <joint name="zed_camera_joint" type="fixed">
            <child>zed_camera::link</child>
            <parent>chassis</parent>
        </joint>

        <include>
            <uri>model://peak_pcan_gps</uri>
            <pose>-1.25 0 0.45 0 0 0</pose>
        </include>

        <joint name="peak_pcan_gps_joint" type="fixed">
            <child>peak_pcan_gps::link</child>
            <parent>chassis</parent>
        </joint>

    </model>

</sdf>
